Workbook

Sheet Main
A1: baseyear | B1: year | C1: month_code | D1: month | E1: state | F1: index | G1: inflation | H1: status | I1: WPI INDEX | J1: WPI INFLATION | L1: CPI Quarterly Inflation | M1: Fiscal Quarter
A2: 2012 | B2: 2025 | C2: 12 | D2: December | E2: All India | F2: 198 | G2: 1.33 | H2: F | I2: 157.2 | J2: =IFERROR(I2/I14-1,"") -> 0.0096339114 | L2: =(AVERAGE(G2:G4)/AVERAGE(G14:G16)-1)*100 -> -86.457717 | M2: =IF(C2="","",(IF(C2>=4,B2,B2-1))&"-"&TEXT(MOD(IF(C2>=4,B2,B2-1)+1,100),"00")&" Q"&IF(C2>=4,ROUNDUP((C2-3)/3,0),ROUNDUP((C2+9)/3,0))) -> 2025-26 Q3
A3: 2012 | B3: 2025 | C3: 11 | D3: November | E3: All India | F3: 197.9 | G3: 0.71 | H3: F | I3: 156.2 | J3: =IFERROR(I3/I15-1,"") -> -0.0012787724 | M3: =IF(C3="","",(IF(C3>=4,B3,B3-1))&"-"&TEXT(MOD(IF(C3>=4,B3,B3-1)+1,100),"00")&" Q"&IF(C3>=4,ROUNDUP((C3-3)/3,0),ROUNDUP((C3+9)/3,0))) -> 2025-26 Q3
A4: 2012 | B4: 2025 | C4: 10 | D4: October | E4: All India | F4: 197.3 | G4: 0.25 | H4: F | I4: 155.1 | J4: =IFERROR(I4/I16-1,"") -> -0.010210593 | M4: =IF(C4="","",(IF(C4>=4,B4,B4-1))&"-"&TEXT(MOD(IF(C4>=4,B4,B4-1)+1,100),"00")&" Q"&IF(C4>=4,ROUNDUP((C4-3)/3,0),ROUNDUP((C4+9)/3,0))) -> 2025-26 Q3
A5: 2012 | B5: 2025 | C5: 9 | D5: September | E5: All India | F5: 197 | G5: 1.44 | H5: F | I5: 155 | J5: =IFERROR(I5/I17-1,"") -> 0.0019392372 | M5: =IF(C5="","",(IF(C5>=4,B5,B5-1))&"-"&TEXT(MOD(IF(C5>=4,B5,B5-1)+1,100),"00")&" Q"&IF(C5>=4,ROUNDUP((C5-3)/3,0),ROUNDUP((C5+9)/3,0))) -> 2025-26 Q2
A6: 2012 | B6: 2025 | C6: 8 | D6: August | E6: All India | F6: 197 | G6: 2.07 | H6: F | I6: 155.2 | J6: =IFERROR(I6/I18-1,"") -> 0.0051813472 | M6: =IF(C6="","",(IF(C6>=4,B6,B6-1))&"-"&TEXT(MOD(IF(C6>=4,B6,B6-1)+1,100),"00")&" Q"&IF(C6>=4,ROUNDUP((C6-3)/3,0),ROUNDUP((C6+9)/3,0))) -> 2025-26 Q2
A7: 2012 | B7: 2025 | C7: 7 | D7: July | E7: All India | F7: 196.1 | G7: 1.61 | H7: F | I7: 154.4 | J7: =IFERROR(I7/I19-1,"") -> -0.005795235 | M7: =IF(C7="","",(IF(C7>=4,B7,B7-1))&"-"&TEXT(MOD(IF(C7>=4,B7,B7-1)+1,100),"00")&" Q"&IF(C7>=4,ROUNDUP((C7-3)/3,0),ROUNDUP((C7+9)/3,0))) -> 2025-26 Q2
A8: 2012 | B8: 2025 | C8: 6 | D8: June | E8: All India | F8: 194.2 | G8: 2.1 | H8: F | I8: 153.7 | J8: =IFERROR(I8/I20-1,"") -> -0.0019480519 | L8: =(AVERAGE(G8:G10)/AVERAGE(G20:G22)-1)*100 -> -45.07138 | M8: =IF(C8="","",(IF(C8>=4,B8,B8-1))&"-"&TEXT(MOD(IF(C8>=4,B8,B8-1)+1,100),"00")&" Q"&IF(C8>=4,ROUNDUP((C8-3)/3,0),ROUNDUP((C8+9)/3,0))) -> 2025-26 Q1
A9: 2012 | B9: 2025 | C9: 5 | D9: May | E9: All India | F9: 193 | G9: 2.82 | H9: F | I9: 153.7 | J9: =IFERROR(I9/I21-1,"") -> 0.0013029316 | M9: =IF(C9="","",(IF(C9>=4,B9,B9-1))&"-"&TEXT(MOD(IF(C9>=4,B9,B9-1)+1,100),"00")&" Q"&IF(C9>=4,ROUNDUP((C9-3)/3,0),ROUNDUP((C9+9)/3,0))) -> 2025-26 Q1
A10: 2012 | B10: 2025 | C10: 4 | D10: April | E10: All India | F10: 192.6 | G10: 3.16 | H10: F | I10: 154.2 | J10: =IFERROR(I10/I22-1,"") -> 0.0085022891 | M10: =IF(C10="","",(IF(C10>=4,B10,B10-1))&"-"&TEXT(MOD(IF(C10>=4,B10,B10-1)+1,100),"00")&" Q"&IF(C10>=4,ROUNDUP((C10-3)/3,0),ROUNDUP((C10+9)/3,0))) -> 2025-26 Q1
A11: 2012 | B11: 2025 | C11: 3 | D11: March | E11: All India | F11: 192 | G11: 3.34 | H11: F | I11: 154.8 | J11: =IFERROR(I11/I23-1,"") -> 0.022457067 | M11: =IF(C11="","",(IF(C11>=4,B11,B11-1))&"-"&TEXT(MOD(IF(C11>=4,B11,B11-1)+1,100),"00")&" Q"&IF(C11>=4,ROUNDUP((C11-3)/3,0),ROUNDUP((C11+9)/3,0))) -> 2024-25 Q4
A12: 2012 | B12: 2025 | C12: 2 | D12: February | E12: All India | F12: 192.5 | G12: 3.61 | H12: F | I12: 154.9 | J12: =IFERROR(I12/I24-1,"") -> 0.024470899 | M12: =IF(C12="","",(IF(C12>=4,B12,B12-1))&"-"&TEXT(MOD(IF(C12>=4,B12,B12-1)+1,100),"00")&" Q"&IF(C12>=4,ROUNDUP((C12-3)/3,0),ROUNDUP((C12+9)/3,0))) -> 2024-25 Q4
A13: 2012 | B13: 2025 | C13: 1 | D13: January | E13: All India | F13: 193.4 | G13: 4.26 | H13: F | I13: 155 | J13: =IFERROR(I13/I25-1,"") -> 0.025132275 | M13: =IF(C13="","",(IF(C13>=4,B13,B13-1))&"-"&TEXT(MOD(IF(C13>=4,B13,B13-1)+1,100),"00")&" Q"&IF(C13>=4,ROUNDUP((C13-3)/3,0),ROUNDUP((C13+9)/3,0))) -> 2024-25 Q4
A14: 2012 | B14: 2024 | C14: 12 | D14: December | E14: All India | F14: 195.4 | G14: 5.22 | H14: F | I14: 155.7 | J14: =IFERROR(I14/I26-1,"") -> 0.0256917 | M14: =IF(C14="","",(IF(C14>=4,B14,B14-1))&"-"&TEXT(MOD(IF(C14>=4,B14,B14-1)+1,100),"00")&" Q"&IF(C14>=4,ROUNDUP((C14-3)/3,0),ROUNDUP((C14+9)/3,0))) -> 2024-25 Q3
A15: 2012 | B15: 2024 | C15: 11 | D15: November | E15: All India | F15: 196.5 | G15: 5.48 | H15: F | I15: 156.4 | J15: =IFERROR(I15/I27-1,"") -> 0.02155454 | M15: =IF(C15="","",(IF(C15>=4,B15,B15-1))&"-"&TEXT(MOD(IF(C15>=4,B15,B15-1)+1,100),"00")&" Q"&IF(C15>=4,ROUNDUP((C15-3)/3,0),ROUNDUP((C15+9)/3,0))) -> 2024-25 Q3
A16: 2012 | B16: 2024 | C16: 10 | D16: October | E16: All India | F16: 196.8 | G16: 6.21 | H16: F | I16: 156.7 | J16: =IFERROR(I16/I28-1,"") -> 0.027540984 | M16: =IF(C16="","",(IF(C16>=4,B16,B16-1))&"-"&TEXT(MOD(IF(C16>=4,B16,B16-1)+1,100),"00")&" Q"&IF(C16>=4,ROUNDUP((C16-3)/3,0),ROUNDUP((C16+9)/3,0))) -> 2024-25 Q3
A17: 2012 | B17: 2024 | C17: 9 | D17: September | E17: All India | F17: 194.2 | G17: 5.49 | H17: F | I17: 154.7 | J17: =IFERROR(I17/I29-1,"") -> 0.019104084 | M17: =IF(C17="","",(IF(C17>=4,B17,B17-1))&"-"&TEXT(MOD(IF(C17>=4,B17,B17-1)+1,100),"00")&" Q"&IF(C17>=4,ROUNDUP((C17-3)/3,0),ROUNDUP((C17+9)/3,0))) -> 2024-25 Q2
A18: 2012 | B18: 2024 | C18: 8 | D18: August | E18: All India | F18: 193 | G18: 3.65 | H18: F | I18: 154.4 | J18: =IFERROR(I18/I30-1,"") -> 0.012459016 | M18: =IF(C18="","",(IF(C18>=4,B18,B18-1))&"-"&TEXT(MOD(IF(C18>=4,B18,B18-1)+1,100),"00")&" Q"&IF(C18>=4,ROUNDUP((C18-3)/3,0),ROUNDUP((C18+9)/3,0))) -> 2024-25 Q2
A19: 2012 | B19: 2024 | C19: 7 | D19: July | E19: All India | F19: 193 | G19: 3.6 | H19: F | I19: 155.3 | J19: =IFERROR(I19/I31-1,"") -> 0.02103879 | M19: =IF(C19="","",(IF(C19>=4,B19,B19-1))&"-"&TEXT(MOD(IF(C19>=4,B19,B19-1)+1,100),"00")&" Q"&IF(C19>=4,ROUNDUP((C19-3)/3,0),ROUNDUP((C19+9)/3,0))) -> 2024-25 Q2
A20: 2012 | B20: 2024 | C20: 6 | D20: June | E20: All India | F20: 190.2 | G20: 5.08 | H20: F | I20: 154 | J20: =IFERROR(I20/I32-1,"") -> 0.034251175 | M20: =IF(C20="","",(IF(C20>=4,B20,B20-1))&"-"&TEXT(MOD(IF(C20>=4,B20,B20-1)+1,100),"00")&" Q"&IF(C20>=4,ROUNDUP((C20-3)/3,0),ROUNDUP((C20+9)/3,0))) -> 2024-25 Q1
... A68: 2012 | B68: 2020 | C68: 6 | D68: June | E68: All India | F68: 151.8 | G68: 6.23 | H68: F | I68: 119.3 | J68: =IFERROR(I68/I80-1,"") -> -0.018106996 | M68: =IF(C68="","",(IF(C68>=4,B68,B68-1))&"-"&TEXT(MOD(IF(C68>=4,B68,B68-1)+1,100),"00")&" Q"&IF(C68>=4,ROUNDUP((C68-3)/3,0),ROUNDUP((C68+9)/3,0))) -> 2020-21 Q1
A69: 2012 | B69: 2020 | C69: 5 | D69: May | E69: All India | F69: 150.9 | H69: F* | I69: 117.5 | J69: =IFERROR(I69/I81-1,"") -> -0.033717105 | M69: =IF(C69="","",(IF(C69>=4,B69,B69-1))&"-"&TEXT(MOD(IF(C69>=4,B69,B69-1)+1,100),"00")&" Q"&IF(C69>=4,ROUNDUP((C69-3)/3,0),ROUNDUP((C69+9)/3,0))) -> 2020-21 Q1
A70: 2012 | B70: 2020 | C70: 4 | D70: April | E70: All India | F70: 151.4 | H70: F* | I70: 119.2 | J70: =IFERROR(I70/I82-1,"") -> -0.015689513 | M70: =IF(C70="","",(IF(C70>=4,B70,B70-1))&"-"&TEXT(MOD(IF(C70>=4,B70,B70-1)+1,100),"00")&" Q"&IF(C70>=4,ROUNDUP((C70-3)/3,0),ROUNDUP((C70+9)/3,0))) -> 2020-21 Q1
A71: 2012 | B71: 2020 | C71: 3 | D71: March | E71: All India | F71: 148.6 | G71: 5.84 | H71: F | I71: 120.4 | J71: =IFERROR(I71/I83-1,"") -> 0.0041701418 | M71: =IF(C71="","",(IF(C71>=4,B71,B71-1))&"-"&TEXT(MOD(IF(C71>=4,B71,B71-1)+1,100),"00")&" Q"&IF(C71>=4,ROUNDUP((C71-3)/3,0),ROUNDUP((C71+9)/3,0))) -> 2019-20 Q4
A72: 2012 | B72: 2020 | C72: 2 | D72: February | E72: All India | F72: 149.1 | G72: 6.58 | H72: F | I72: 122.2 | J72: =IFERROR(I72/I84-1,"") -> 0.022594142 | M72: =IF(C72="","",(IF(C72>=4,B72,B72-1))&"-"&TEXT(MOD(IF(C72>=4,B72,B72-1)+1,100),"00")&" Q"&IF(C72>=4,ROUNDUP((C72-3)/3,0),ROUNDUP((C72+9)/3,0))) -> 2019-20 Q4
A73: 2012 | B73: 2020 | C73: 1 | D73: January | E73: All India | F73: 150.2 | G73: 7.59 | H73: F | I73: 123.4 | J73: =IFERROR(I73/I85-1,"") -> 0.035234899 | M73: =IF(C73="","",(IF(C73>=4,B73,B73-1))&"-"&TEXT(MOD(IF(C73>=4,B73,B73-1)+1,100),"00")&" Q"&IF(C73>=4,ROUNDUP((C73-3)/3,0),ROUNDUP((C73+9)/3,0))) -> 2019-20 Q4
A74: 2012 | B74: 2019 | C74: 12 | D74: December | E74: All India | F74: 150.4 | G74: 7.35 | H74: F | I74: 123 | J74: =IFERROR(I74/I86-1,"") -> 0.027568922 | M74: =IF(C74="","",(IF(C74>=4,B74,B74-1))&"-"&TEXT(MOD(IF(C74>=4,B74,B74-1)+1,100),"00")&" Q"&IF(C74>=4,ROUNDUP((C74-3)/3,0),ROUNDUP((C74+9)/3,0))) -> 2019-20 Q3
A75: 2012 | B75: 2019 | C75: 11 | D75: November | E75: All India | F75: 148.6 | G75: 5.54 | H75: F | I75: 122.3 | J75: =IFERROR(I75/I87-1,"") -> 0.0057565789 | M75: =IF(C75="","",(IF(C75>=4,B75,B75-1))&"-"&TEXT(MOD(IF(C75>=4,B75,B75-1)+1,100),"00")&" Q"&IF(C75>=4,ROUNDUP((C75-3)/3,0),ROUNDUP((C75+9)/3,0))) -> 2019-20 Q3
A76: 2012 | B76: 2019 | C76: 10 | D76: October | E76: All India | F76: 147.2 | G76: 4.62 | H76: F | I76: 122 | J76: =IFERROR(I76/I88-1,"") -> 0 | M76: =IF(C76="","",(IF(C76>=4,B76,B76-1))&"-"&TEXT(MOD(IF(C76>=4,B76,B76-1)+1,100),"00")&" Q"&IF(C76>=4,ROUNDUP((C76-3)/3,0),ROUNDUP((C76+9)/3,0))) -> 2019-20 Q3
A77: 2012 | B77: 2019 | C77: 9 | D77: September | E77: All India | F77: 145.8 | G77: 3.99 | H77: F | I77: 121.3 | J77: =IFERROR(I77/I89-1,"") -> 0.0033085194 | M77: =IF(C77="","",(IF(C77>=4,B77,B77-1))&"-"&TEXT(MOD(IF(C77>=4,B77,B77-1)+1,100),"00")&" Q"&IF(C77>=4,ROUNDUP((C77-3)/3,0),ROUNDUP((C77+9)/3,0))) -> 2019-20 Q2
A78: 2012 | B78: 2019 | C78: 8 | D78: August | E78: All India | F78: 145 | G78: 3.28 | H78: F | I78: 121.5 | J78: =IFERROR(I78/I90-1,"") -> 0.011656953 | M78: =IF(C78="","",(IF(C78>=4,B78,B78-1))&"-"&TEXT(MOD(IF(C78>=4,B78,B78-1)+1,100),"00")&" Q"&IF(C78>=4,ROUNDUP((C78-3)/3,0),ROUNDUP((C78+9)/3,0))) -> 2019-20 Q2
A79: 2012 | B79: 2019 | C79: 7 | D79: July | E79: All India | F79: 144.2 | G79: 3.15 | H79: F | I79: 121.3 | J79: =IFERROR(I79/I91-1,"") -> 0.011676397 | M79: =IF(C79="","",(IF(C79>=4,B79,B79-1))&"-"&TEXT(MOD(IF(C79>=4,B79,B79-1)+1,100),"00")&" Q"&IF(C79>=4,ROUNDUP((C79-3)/3,0),ROUNDUP((C79+9)/3,0))) -> 2019-20 Q2
A80: 2012 | B80: 2019 | C80: 6 | D80: June | E80: All India | F80: 142.9 | G80: 3.18 | H80: F | I80: 121.5 | J80: =IFERROR(I80/I92-1,"") -> 0.020151134 | M80: =IF(C80="","",(IF(C80>=4,B80,B80-1))&"-"&TEXT(MOD(IF(C80>=4,B80,B80-1)+1,100),"00")&" Q"&IF(C80>=4,ROUNDUP((C80-3)/3,0),ROUNDUP((C80+9)/3,0))) -> 2019-20 Q1
A81: 2012 | B81: 2019 | C81: 5 | D81: May | E81: All India | F81: 142 | G81: 3.05 | H81: F | I81: 121.6 | J81: =IFERROR(I81/I93-1,"") -> 0.027895182 | M81: =IF(C81="","",(IF(C81>=4,B81,B81-1))&"-"&TEXT(MOD(IF(C81>=4,B81,B81-1)+1,100),"00")&" Q"&IF(C81>=4,ROUNDUP((C81-3)/3,0),ROUNDUP((C81+9)/3,0))) -> 2019-20 Q1
A82: 2012 | B82: 2019 | C82: 4 | D82: April | E82: All India | F82: 141.2 | G82: 2.99 | H82: F | I82: 121.1 | J82: =IFERROR(I82/I94-1,"") -> 0.032395567 | M82: =IF(C82="","",(IF(C82>=4,B82,B82-1))&"-"&TEXT(MOD(IF(C82>=4,B82,B82-1)+1,100),"00")&" Q"&IF(C82>=4,ROUNDUP((C82-3)/3,0),ROUNDUP((C82+9)/3,0))) -> 2019-20 Q1
... A145: 2012 | B145: 2014 | C145: 1 | D145: January | E145: All India | F145: 113.6 | G145: 8.6 | H145: F | I145: 113.6 | J145: =IFERROR(I145/I157-1,"") -> 0.051851852 | M145: =IF(C145="","",(IF(C145>=4,B145,B145-1))&"-"&TEXT(MOD(IF(C145>=4,B145,B145-1)+1,100),"00")&" Q"&IF(C145>=4,ROUNDUP((C145-3)/3,0),ROUNDUP((C145+9)/3,0))) -> 2013-14 Q4
A146: 2012 | B146: 2013 | C146: 12 | D146: December | E146: All India | F146: 114.5 | H146: F | I146: 113.4 | J146: =IFERROR(I146/I158-1,"") | M146: =IF(C146="","",(IF(C146>=4,B146,B146-1))&"-"&TEXT(MOD(IF(C146>=4,B146,B146-1)+1,100),"00")&" Q"&IF(C146>=4,ROUNDUP((C146-3)/3,0),ROUNDUP((C146+9)/3,0))) -> 2013-14 Q3
A147: 2012 | B147: 2013 | C147: 11 | D147: November | E147: All India | F147: 116.3 | H147: F | I147: 114.3 | J147: =IFERROR(I147/I159-1,"") | M147: =IF(C147="","",(IF(C147>=4,B147,B147-1))&"-"&TEXT(MOD(IF(C147>=4,B147,B147-1)+1,100),"00")&" Q"&IF(C147>=4,ROUNDUP((C147-3)/3,0),ROUNDUP((C147+9)/3,0))) -> 2013-14 Q3
A148: 2012 | B148: 2013 | C148: 10 | D148: October | E148: All India | F148: 114.8 | H148: F | I148: 114.6 | J148: =IFERROR(I148/I160-1,"") | M148: =IF(C148="","",(IF(C148>=4,B148,B148-1))&"-"&TEXT(MOD(IF(C148>=4,B148,B148-1)+1,100),"00")&" Q"&IF(C148>=4,ROUNDUP((C148-3)/3,0),ROUNDUP((C148+9)/3,0))) -> 2013-14 Q3
A149: 2012 | B149: 2013 | C149: 9 | D149: September | E149: All India | F149: 113.7 | H149: F | I149: 114.3 | J149: =IFERROR(I149/I161-1,"") | M149: =IF(C149="","",(IF(C149>=4,B149,B149-1))&"-"&TEXT(MOD(IF(C149>=4,B149,B149-1)+1,100),"00")&" Q"&IF(C149>=4,ROUNDUP((C149-3)/3,0),ROUNDUP((C149+9)/3,0))) -> 2013-14 Q2
...

Sheet cpi quarterly
A1: Period | B1: CPI Quarterly Index | C1: CPI Inflation YoY | D1: WPI Quarterly Index | E1: WPI Inflation YoY | G1: Notes
A2: 2011-12 Q1 | B2: =IFERROR(AVERAGEIF(Main!$M:$M,$A2,Main!$F:$F),"") | D2: =IFERROR(AVERAGEIF(Main!$M:$M,$A2,Main!$I:$I),"") | G2: Quarterly Index = simple average of the 3 monthly index values in that India fiscal-year quarter (Apr-Jun=Q1 ... Jan-Mar=Q4), via Main!Fiscal Quarter helper column.
A3: 2011-12 Q2 | B3: =IFERROR(AVERAGEIF(Main!$M:$M,$A3,Main!$F:$F),"") | D3: =IFERROR(AVERAGEIF(Main!$M:$M,$A3,Main!$I:$I),"") | G3: YoY Inflation = (This quarter Index / Same quarter, prior fiscal year Index) - 1, i.e. compared to the row 4 above.
A4: 2011-12 Q3 | B4: =IFERROR(AVERAGEIF(Main!$M:$M,$A4,Main!$F:$F),"") | D4: =IFERROR(AVERAGEIF(Main!$M:$M,$A4,Main!$I:$I),"") | G4: Blank cells mean the underlying monthly CPI/WPI index data (Main sheet) does not cover all 3 months of that quarter.
A5: 2011-12 Q4 | B5: =IFERROR(AVERAGEIF(Main!$M:$M,$A5,Main!$F:$F),"") | D5: =IFERROR(AVERAGEIF(Main!$M:$M,$A5,Main!$I:$I),"")
A6: 2012-13 Q1 | B6: =IFERROR(AVERAGEIF(Main!$M:$M,$A6,Main!$F:$F),"") | C6: =IFERROR(B6/B2-1,"") | D6: =IFERROR(AVERAGEIF(Main!$M:$M,$A6,Main!$I:$I),"") | E6: =IFERROR(D6/D2-1,"")
A7: 2012-13 Q2 | B7: =IFERROR(AVERAGEIF(Main!$M:$M,$A7,Main!$F:$F),"") | C7: =IFERROR(B7/B3-1,"") | D7: =IFERROR(AVERAGEIF(Main!$M:$M,$A7,Main!$I:$I),"") | E7: =IFERROR(D7/D3-1,"")
A8: 2012-13 Q3 | B8: =IFERROR(AVERAGEIF(Main!$M:$M,$A8,Main!$F:$F),"") | C8: =IFERROR(B8/B4-1,"") | D8: =IFERROR(AVERAGEIF(Main!$M:$M,$A8,Main!$I:$I),"") | E8: =IFERROR(D8/D4-1,"")
A9: 2012-13 Q4 | B9: =IFERROR(AVERAGEIF(Main!$M:$M,$A9,Main!$F:$F),"") -> 105.13333 | C9: =IFERROR(B9/B5-1,"") | D9: =IFERROR(AVERAGEIF(Main!$M:$M,$A9,Main!$I:$I),"") -> 108.33333 | E9: =IFERROR(D9/D5-1,"")
A10: 2013-14 Q1 | B10: =IFERROR(AVERAGEIF(Main!$M:$M,$A10,Main!$F:$F),"") -> 107.43333 | C10: =IFERROR(B10/B6-1,"") | D10: =IFERROR(AVERAGEIF(Main!$M:$M,$A10,Main!$I:$I),"") -> 109.1 | E10: =IFERROR(D10/D6-1,"")
A11: 2013-14 Q2 | B11: =IFERROR(AVERAGEIF(Main!$M:$M,$A11,Main!$F:$F),"") -> 112.36667 | C11: =IFERROR(B11/B7-1,"") | D11: =IFERROR(AVERAGEIF(Main!$M:$M,$A11,Main!$I:$I),"") -> 112.8 | E11: =IFERROR(D11/D7-1,"")
A12: 2013-14 Q3 | B12: =IFERROR(AVERAGEIF(Main!$M:$M,$A12,Main!$F:$F),"") -> 115.2 | C12: =IFERROR(B12/B8-1,"") | D12: =IFERROR(AVERAGEIF(Main!$M:$M,$A12,Main!$I:$I),"") -> 114.1 | E12: =IFERROR(D12/D8-1,"")
A13: 2013-14 Q4 | B13: =IFERROR(AVERAGEIF(Main!$M:$M,$A13,Main!$F:$F),"") -> 113.8 | C13: =IFERROR(B13/B9-1,"") -> 0.082435003 | D13: =IFERROR(AVERAGEIF(Main!$M:$M,$A13,Main!$I:$I),"") -> 113.83333 | E13: =IFERROR(D13/D9-1,"") -> 0.050769231
A14: 2014-15 Q1 | B14: =IFERROR(AVERAGEIF(Main!$M:$M,$A14,Main!$F:$F),"") -> 115.86667 | C14: =IFERROR(B14/B10-1,"") -> 0.078498294 | D14: =IFERROR(AVERAGEIF(Main!$M:$M,$A14,Main!$I:$I),"") -> 114.7 | E14: =IFERROR(D14/D10-1,"") -> 0.051329056
A15: 2014-15 Q2 | B15: =IFERROR(AVERAGEIF(Main!$M:$M,$A15,Main!$F:$F),"") -> 119.86667 | C15: =IFERROR(B15/B11-1,"") -> 0.066745773 | D15: =IFERROR(AVERAGEIF(Main!$M:$M,$A15,Main!$I:$I),"") -> 116.76667 | E15: =IFERROR(D15/D11-1,"") -> 0.035165485
A16: 2014-15 Q3 | B16: =IFERROR(AVERAGEIF(Main!$M:$M,$A16,Main!$F:$F),"") -> 119.86667 | C16: =IFERROR(B16/B12-1,"") -> 0.040509259 | D16: =IFERROR(AVERAGEIF(Main!$M:$M,$A16,Main!$I:$I),"") -> 113.93333 | E16: =IFERROR(D16/D12-1,"") -> -0.001460707
A17: 2014-15 Q4 | B17: =IFERROR(AVERAGEIF(Main!$M:$M,$A17,Main!$F:$F),"") -> 119.8 | C17: =IFERROR(B17/B13-1,"") -> 0.052724077 | D17: =IFERROR(AVERAGEIF(Main!$M:$M,$A17,Main!$I:$I),"") -> 110.1 | E17: =IFERROR(D17/D13-1,"") -> -0.032796486
... A59: 2025-26 Q2 | B59: =IFERROR(AVERAGEIF(Main!$M:$M,$A59,Main!$F:$F),"") -> 196.7 | C59: =IFERROR(B59/B55-1,"") -> 0.017063082 | D59: =IFERROR(AVERAGEIF(Main!$M:$M,$A59,Main!$I:$I),"") -> 154.86667 | E59: =IFERROR(D59/D55-1,"") -> 0.00043066322

Sheet quarterly data
A1: Period | B1: Real GDP | C1: Nominal GDP | D1: GDP Deflator | E1: Deflator YoY
A2: 2011-12 Q1 | B2: 2102862.8 | C2: 2043496.3 | D2: =C2/B2*100 -> 97.176871
A3: 2011-12 Q2 | B3: 2042870.2 | C3: 2029469.2 | D3: =C3/B3*100 -> 99.344011
A4: 2011-12 Q3 | B4: 2225135.2 | C4: 2244852.2 | D4: =C4/B4*100 -> 100.8861
A5: 2011-12 Q4 | B5: 2365461.4 | C5: 2418511.1 | D5: =C5/B5*100 -> 102.24268
A6: 2012-13 Q1 | B6: 2205223.4 | C6: 2313203.1 | D6: =C6/B6*100 -> 104.89654 | E6: =D6/D2-1 -> 0.079439366
A7: 2012-13 Q2 | B7: 2195945.9 | C7: 2356953.3 | D7: =C7/B7*100 -> 107.33203 | E7: =D7/D3-1 -> 0.080407648
A8: 2012-13 Q3 | B8: 2344767.2 | C8: 2548377.8 | D8: =C8/B8*100 -> 108.68362 | E8: =D8/D4-1 -> 0.077290267
A9: 2012-13 Q4 | B9: 2467081.9 | C9: 2725478.9 | D9: =C9/B9*100 -> 110.47379 | E9: =D9/D5-1 -> 0.080505646
A10: 2013-14 Q1 | B10: 2347396.4 | C10: 2565374.4 | D10: =C10/B10*100 -> 109.28595 | E10: =D10/D6-1 -> 0.041845143
A11: 2013-14 Q2 | B11: 2357078.9 | C11: 2686203.2 | D11: =C11/B11*100 -> 113.96323 | E11: =D11/D7-1 -> 0.061782128
A12: 2013-14 Q3 | B12: 2497997.3 | C12: 2921070 | D12: =C12/B12*100 -> 116.93648 | E12: =D12/D8-1 -> 0.0759347
A13: 2013-14 Q4 | B13: 2598897.6 | C13: 3060874.1 | D13: =C13/B13*100 -> 117.77587 | E13: =D13/D9-1 -> 0.066097796
A14: 2014-15 Q1 | B14: 2535750.6 | C14: 2914393.2 | D14: =C14/B14*100 -> 114.93217 | E14: =D14/D10-1 -> 0.051664655
A15: 2014-15 Q2 | B15: 2562241.6 | C15: 3053982 | D15: =C15/B15*100 -> 119.19181 | E15: =D15/D11-1 -> 0.045879498
A16: 2014-15 Q3 | B16: 2645947.1 | C16: 3184917.1 | D16: =C16/B16*100 -> 120.36964 | E16: =D16/D12-1 -> 0.029359236
A17: 2014-15 Q4 | B17: 2783733.2 | C17: 3314666.8 | D17: =C17/B17*100 -> 119.07272 | E17: =D17/D13-1 -> 0.011011171
... A59: 2025-26 Q2 | B59: 4863340.2 | C59: 8525069.5 | D59: =C59/B59*100 -> 175.29248 | E59: =D59/D55-1 -> 0.0046648685

Sheet Regression Data
A1: Period | B1: CPI Inflation YoY | C1: WPI Inflation YoY | D1: Deflator YoY
A2: 2011-12 Q1
A3: 2011-12 Q2
A4: 2011-12 Q3
A5: 2011-12 Q4
A6: 2012-13 Q1 | D6: 0.079439366
A7: 2012-13 Q2 | D7: 0.080407648
A8: 2012-13 Q3 | D8: 0.077290267
A9: 2012-13 Q4 | D9: 0.080505646
A10: 2013-14 Q1 | D10: 0.041845143
A11: 2013-14 Q2 | D11: 0.061782128
A12: 2013-14 Q3 | D12: 0.0759347
A13: 2013-14 Q4 | B13: 0.082435003 | C13: 0.050769231 | D13: 0.066097796
A14: 2014-15 Q1 | B14: 0.078498294 | C14: 0.051329056 | D14: 0.051664655
A15: 2014-15 Q2 | B15: 0.066745773 | C15: 0.035165485 | D15: 0.045879498
A16: 2014-15 Q3 | B16: 0.040509259 | C16: -0.001460707 | D16: 0.029359236
A17: 2014-15 Q4 | B17: 0.052724077 | C17: -0.032796486 | D17: 0.011011171
A18: 2015-16 Q1 | B18: 0.050920598 | C18: -0.031095612 | D18: 0.034402069
A19: 2015-16 Q2 | B19: 0.03948832 | C19: -0.055095632 | D19: 0.017140253
A20: 2015-16 Q3 | B20: 0.053392659 | C20: -0.036278525 | D20: 0.018301235
A21: 2015-16 Q4 | B21: 0.052587646 | C21: -0.02270663 | D21: 0.02209317
A22: 2016-17 Q1 | B22: 0.056665754 | C22: -0.0068986203 | D22: 0.032537758
A23: 2016-17 Q2 | B23: 0.051631889 | C23: 0.010271903 | D23: 0.020031834
A24: 2016-17 Q3 | B24: 0.0374868 | C24: 0.017304189 | D24: 0.026554152
... A59: 2025-26 Q2 | B59: 0.017063082 | C59: 0.00043066322 | D59: 0.0046648685
